[2023-09-23T13:54:25.606+0000] {processor.py:157} INFO - Started process (PID=13090) to work on /workspaces/hands-on-introduction-data-engineering-4395021/airflow/dags/one-task-dag.py
[2023-09-23T13:54:25.606+0000] {processor.py:829} INFO - Processing file /workspaces/hands-on-introduction-data-engineering-4395021/airflow/dags/one-task-dag.py for tasks to queue
[2023-09-23T13:54:25.607+0000] {logging_mixin.py:151} INFO - [2023-09-23T13:54:25.607+0000] {dagbag.py:539} INFO - Filling up the DagBag from /workspaces/hands-on-introduction-data-engineering-4395021/airflow/dags/one-task-dag.py
[2023-09-23T13:54:25.610+0000] {logging_mixin.py:151} INFO - [2023-09-23T13:54:25.608+0000] {dagbag.py:347} ERROR - Failed to import: /workspaces/hands-on-introduction-data-engineering-4395021/airflow/dags/one-task-dag.py
Traceback (most recent call last):
  File "/usr/local/python/3.10.8/lib/python3.10/site-packages/airflow/models/dagbag.py", line 343, in parse
    loader.exec_module(new_module)
  File "<frozen importlib._bootstrap_external>", line 879, in exec_module
  File "<frozen importlib._bootstrap_external>", line 1017, in get_code
  File "<frozen importlib._bootstrap_external>", line 947, in source_to_code
  File "<frozen importlib._bootstrap>", line 241, in _call_with_frames_removed
  File "/workspaces/hands-on-introduction-data-engineering-4395021/airflow/dags/one-task-dag.py", line 17
    description='A one task Airflow DAG'
                ^
SyntaxError: invalid syntax. Perhaps you forgot a comma?
[2023-09-23T13:54:25.610+0000] {processor.py:841} WARNING - No viable dags retrieved from /workspaces/hands-on-introduction-data-engineering-4395021/airflow/dags/one-task-dag.py
[2023-09-23T13:54:25.656+0000] {processor.py:179} INFO - Processing /workspaces/hands-on-introduction-data-engineering-4395021/airflow/dags/one-task-dag.py took 0.051 seconds
[2023-09-23T13:54:35.533+0000] {processor.py:157} INFO - Started process (PID=13185) to work on /workspaces/hands-on-introduction-data-engineering-4395021/airflow/dags/one-task-dag.py
[2023-09-23T13:54:35.533+0000] {processor.py:829} INFO - Processing file /workspaces/hands-on-introduction-data-engineering-4395021/airflow/dags/one-task-dag.py for tasks to queue
[2023-09-23T13:54:35.534+0000] {logging_mixin.py:151} INFO - [2023-09-23T13:54:35.533+0000] {dagbag.py:539} INFO - Filling up the DagBag from /workspaces/hands-on-introduction-data-engineering-4395021/airflow/dags/one-task-dag.py
[2023-09-23T13:54:35.536+0000] {logging_mixin.py:151} INFO - [2023-09-23T13:54:35.535+0000] {dagbag.py:347} ERROR - Failed to import: /workspaces/hands-on-introduction-data-engineering-4395021/airflow/dags/one-task-dag.py
Traceback (most recent call last):
  File "/usr/local/python/3.10.8/lib/python3.10/site-packages/airflow/models/dagbag.py", line 343, in parse
    loader.exec_module(new_module)
  File "<frozen importlib._bootstrap_external>", line 879, in exec_module
  File "<frozen importlib._bootstrap_external>", line 1017, in get_code
  File "<frozen importlib._bootstrap_external>", line 947, in source_to_code
  File "<frozen importlib._bootstrap>", line 241, in _call_with_frames_removed
  File "/workspaces/hands-on-introduction-data-engineering-4395021/airflow/dags/one-task-dag.py", line 22
    bash_command='echo "Hello, this is a course exerices'
                 
SyntaxError: invalid syntax. Perhaps you forgot a comma?
[2023-09-23T13:54:35.536+0000] {processor.py:841} WARNING - No viable dags retrieved from /workspaces/hands-on-introduction-data-engineering-4395021/airflow/dags/one-task-dag.py
[2023-09-23T13:54:35.579+0000] {processor.py:179} INFO - Processing /workspaces/hands-on-introduction-data-engineering-4395021/airflow/dags/one-task-dag.py took 0.048 seconds
[2023-09-23T13:54:36.668+0000] {processor.py:157} INFO - Started process (PID=13193) to work on /workspaces/hands-on-introduction-data-engineering-4395021/airflow/dags/one-task-dag.py
[2023-09-23T13:54:36.668+0000] {processor.py:829} INFO - Processing file /workspaces/hands-on-introduction-data-engineering-4395021/airflow/dags/one-task-dag.py for tasks to queue
[2023-09-23T13:54:36.669+0000] {logging_mixin.py:151} INFO - [2023-09-23T13:54:36.668+0000] {dagbag.py:539} INFO - Filling up the DagBag from /workspaces/hands-on-introduction-data-engineering-4395021/airflow/dags/one-task-dag.py
[2023-09-23T13:54:36.671+0000] {logging_mixin.py:151} INFO - [2023-09-23T13:54:36.670+0000] {dagbag.py:347} ERROR - Failed to import: /workspaces/hands-on-introduction-data-engineering-4395021/airflow/dags/one-task-dag.py
Traceback (most recent call last):
  File "/usr/local/python/3.10.8/lib/python3.10/site-packages/airflow/models/dagbag.py", line 343, in parse
    loader.exec_module(new_module)
  File "<frozen importlib._bootstrap_external>", line 879, in exec_module
  File "<frozen importlib._bootstrap_external>", line 1017, in get_code
  File "<frozen importlib._bootstrap_external>", line 947, in source_to_code
  File "<frozen importlib._bootstrap>", line 241, in _call_with_frames_removed
  File "/workspaces/hands-on-introduction-data-engineering-4395021/airflow/dags/one-task-dag.py", line 22
    bash_command='echo "Hello, this is a course exerices'
                 
SyntaxError: invalid syntax. Perhaps you forgot a comma?
[2023-09-23T13:54:36.671+0000] {processor.py:841} WARNING - No viable dags retrieved from /workspaces/hands-on-introduction-data-engineering-4395021/airflow/dags/one-task-dag.py
[2023-09-23T13:54:36.717+0000] {processor.py:179} INFO - Processing /workspaces/hands-on-introduction-data-engineering-4395021/airflow/dags/one-task-dag.py took 0.051 seconds
[2023-09-23T13:54:50.764+0000] {processor.py:157} INFO - Started process (PID=13277) to work on /workspaces/hands-on-introduction-data-engineering-4395021/airflow/dags/one-task-dag.py
[2023-09-23T13:54:50.765+0000] {processor.py:829} INFO - Processing file /workspaces/hands-on-introduction-data-engineering-4395021/airflow/dags/one-task-dag.py for tasks to queue
[2023-09-23T13:54:50.766+0000] {logging_mixin.py:151} INFO - [2023-09-23T13:54:50.766+0000] {dagbag.py:539} INFO - Filling up the DagBag from /workspaces/hands-on-introduction-data-engineering-4395021/airflow/dags/one-task-dag.py
[2023-09-23T13:54:50.770+0000] {logging_mixin.py:151} INFO - [2023-09-23T13:54:50.769+0000] {dagbag.py:347} ERROR - Failed to import: /workspaces/hands-on-introduction-data-engineering-4395021/airflow/dags/one-task-dag.py
Traceback (most recent call last):
  File "/usr/local/python/3.10.8/lib/python3.10/site-packages/airflow/models/dagbag.py", line 343, in parse
    loader.exec_module(new_module)
  File "<frozen importlib._bootstrap_external>", line 883, in exec_module
  File "<frozen importlib._bootstrap>", line 241, in _call_with_frames_removed
  File "/workspaces/hands-on-introduction-data-engineering-4395021/airflow/dags/one-task-dag.py", line 15, in <module>
    with DAG(
TypeError: DAG.__init__() got an unexpected keyword argument 'schedule_args'
[2023-09-23T13:54:50.771+0000] {processor.py:841} WARNING - No viable dags retrieved from /workspaces/hands-on-introduction-data-engineering-4395021/airflow/dags/one-task-dag.py
[2023-09-23T13:54:50.836+0000] {processor.py:179} INFO - Processing /workspaces/hands-on-introduction-data-engineering-4395021/airflow/dags/one-task-dag.py took 0.074 seconds
[2023-09-23T13:54:55.825+0000] {processor.py:157} INFO - Started process (PID=13324) to work on /workspaces/hands-on-introduction-data-engineering-4395021/airflow/dags/one-task-dag.py
[2023-09-23T13:54:55.826+0000] {processor.py:829} INFO - Processing file /workspaces/hands-on-introduction-data-engineering-4395021/airflow/dags/one-task-dag.py for tasks to queue
[2023-09-23T13:54:55.827+0000] {logging_mixin.py:151} INFO - [2023-09-23T13:54:55.827+0000] {dagbag.py:539} INFO - Filling up the DagBag from /workspaces/hands-on-introduction-data-engineering-4395021/airflow/dags/one-task-dag.py
[2023-09-23T13:54:55.831+0000] {logging_mixin.py:151} INFO - [2023-09-23T13:54:55.830+0000] {dagbag.py:347} ERROR - Failed to import: /workspaces/hands-on-introduction-data-engineering-4395021/airflow/dags/one-task-dag.py
Traceback (most recent call last):
  File "/usr/local/python/3.10.8/lib/python3.10/site-packages/airflow/models/dagbag.py", line 343, in parse
    loader.exec_module(new_module)
  File "<frozen importlib._bootstrap_external>", line 883, in exec_module
  File "<frozen importlib._bootstrap>", line 241, in _call_with_frames_removed
  File "/workspaces/hands-on-introduction-data-engineering-4395021/airflow/dags/one-task-dag.py", line 15, in <module>
    with DAG(
TypeError: DAG.__init__() got an unexpected keyword argument 'schedule_args'
[2023-09-23T13:54:55.831+0000] {processor.py:841} WARNING - No viable dags retrieved from /workspaces/hands-on-introduction-data-engineering-4395021/airflow/dags/one-task-dag.py
[2023-09-23T13:54:55.878+0000] {processor.py:179} INFO - Processing /workspaces/hands-on-introduction-data-engineering-4395021/airflow/dags/one-task-dag.py took 0.055 seconds
[2023-09-23T13:55:04.074+0000] {processor.py:157} INFO - Started process (PID=13368) to work on /workspaces/hands-on-introduction-data-engineering-4395021/airflow/dags/one-task-dag.py
[2023-09-23T13:55:04.074+0000] {processor.py:829} INFO - Processing file /workspaces/hands-on-introduction-data-engineering-4395021/airflow/dags/one-task-dag.py for tasks to queue
[2023-09-23T13:55:04.080+0000] {logging_mixin.py:151} INFO - [2023-09-23T13:55:04.080+0000] {dagbag.py:539} INFO - Filling up the DagBag from /workspaces/hands-on-introduction-data-engineering-4395021/airflow/dags/one-task-dag.py
[2023-09-23T13:55:04.083+0000] {logging_mixin.py:151} INFO - [2023-09-23T13:55:04.082+0000] {dagbag.py:347} ERROR - Failed to import: /workspaces/hands-on-introduction-data-engineering-4395021/airflow/dags/one-task-dag.py
Traceback (most recent call last):
  File "/usr/local/python/3.10.8/lib/python3.10/site-packages/airflow/models/dagbag.py", line 343, in parse
    loader.exec_module(new_module)
  File "<frozen importlib._bootstrap_external>", line 883, in exec_module
  File "<frozen importlib._bootstrap>", line 241, in _call_with_frames_removed
  File "/workspaces/hands-on-introduction-data-engineering-4395021/airflow/dags/one-task-dag.py", line 15, in <module>
    with DAG(
TypeError: DAG.__init__() got an unexpected keyword argument 'schedule_args'
[2023-09-23T13:55:04.084+0000] {processor.py:841} WARNING - No viable dags retrieved from /workspaces/hands-on-introduction-data-engineering-4395021/airflow/dags/one-task-dag.py
[2023-09-23T13:55:04.141+0000] {processor.py:179} INFO - Processing /workspaces/hands-on-introduction-data-engineering-4395021/airflow/dags/one-task-dag.py took 0.076 seconds
[2023-09-23T13:55:34.403+0000] {processor.py:157} INFO - Started process (PID=13569) to work on /workspaces/hands-on-introduction-data-engineering-4395021/airflow/dags/one-task-dag.py
[2023-09-23T13:55:34.404+0000] {processor.py:829} INFO - Processing file /workspaces/hands-on-introduction-data-engineering-4395021/airflow/dags/one-task-dag.py for tasks to queue
[2023-09-23T13:55:34.404+0000] {logging_mixin.py:151} INFO - [2023-09-23T13:55:34.404+0000] {dagbag.py:539} INFO - Filling up the DagBag from /workspaces/hands-on-introduction-data-engineering-4395021/airflow/dags/one-task-dag.py
[2023-09-23T13:55:34.406+0000] {logging_mixin.py:151} INFO - [2023-09-23T13:55:34.406+0000] {dagbag.py:347} ERROR - Failed to import: /workspaces/hands-on-introduction-data-engineering-4395021/airflow/dags/one-task-dag.py
Traceback (most recent call last):
  File "/usr/local/python/3.10.8/lib/python3.10/site-packages/airflow/models/dagbag.py", line 343, in parse
    loader.exec_module(new_module)
  File "<frozen importlib._bootstrap_external>", line 883, in exec_module
  File "<frozen importlib._bootstrap>", line 241, in _call_with_frames_removed
  File "/workspaces/hands-on-introduction-data-engineering-4395021/airflow/dags/one-task-dag.py", line 15, in <module>
    with DAG(
TypeError: DAG.__init__() got an unexpected keyword argument 'schedule_args'
[2023-09-23T13:55:34.406+0000] {processor.py:841} WARNING - No viable dags retrieved from /workspaces/hands-on-introduction-data-engineering-4395021/airflow/dags/one-task-dag.py
[2023-09-23T13:55:34.450+0000] {processor.py:179} INFO - Processing /workspaces/hands-on-introduction-data-engineering-4395021/airflow/dags/one-task-dag.py took 0.048 seconds
[2023-09-23T13:56:04.865+0000] {processor.py:157} INFO - Started process (PID=13760) to work on /workspaces/hands-on-introduction-data-engineering-4395021/airflow/dags/one-task-dag.py
[2023-09-23T13:56:04.866+0000] {processor.py:829} INFO - Processing file /workspaces/hands-on-introduction-data-engineering-4395021/airflow/dags/one-task-dag.py for tasks to queue
[2023-09-23T13:56:04.867+0000] {logging_mixin.py:151} INFO - [2023-09-23T13:56:04.866+0000] {dagbag.py:539} INFO - Filling up the DagBag from /workspaces/hands-on-introduction-data-engineering-4395021/airflow/dags/one-task-dag.py
[2023-09-23T13:56:04.869+0000] {logging_mixin.py:151} INFO - [2023-09-23T13:56:04.868+0000] {dagbag.py:347} ERROR - Failed to import: /workspaces/hands-on-introduction-data-engineering-4395021/airflow/dags/one-task-dag.py
Traceback (most recent call last):
  File "/usr/local/python/3.10.8/lib/python3.10/site-packages/airflow/models/dagbag.py", line 343, in parse
    loader.exec_module(new_module)
  File "<frozen importlib._bootstrap_external>", line 883, in exec_module
  File "<frozen importlib._bootstrap>", line 241, in _call_with_frames_removed
  File "/workspaces/hands-on-introduction-data-engineering-4395021/airflow/dags/one-task-dag.py", line 15, in <module>
    with DAG(
TypeError: DAG.__init__() got an unexpected keyword argument 'schedule_args'
[2023-09-23T13:56:04.870+0000] {processor.py:841} WARNING - No viable dags retrieved from /workspaces/hands-on-introduction-data-engineering-4395021/airflow/dags/one-task-dag.py
[2023-09-23T13:56:04.917+0000] {processor.py:179} INFO - Processing /workspaces/hands-on-introduction-data-engineering-4395021/airflow/dags/one-task-dag.py took 0.055 seconds
[2023-09-23T13:56:35.373+0000] {processor.py:157} INFO - Started process (PID=13957) to work on /workspaces/hands-on-introduction-data-engineering-4395021/airflow/dags/one-task-dag.py
[2023-09-23T13:56:35.376+0000] {processor.py:829} INFO - Processing file /workspaces/hands-on-introduction-data-engineering-4395021/airflow/dags/one-task-dag.py for tasks to queue
[2023-09-23T13:56:35.377+0000] {logging_mixin.py:151} INFO - [2023-09-23T13:56:35.376+0000] {dagbag.py:539} INFO - Filling up the DagBag from /workspaces/hands-on-introduction-data-engineering-4395021/airflow/dags/one-task-dag.py
[2023-09-23T13:56:35.381+0000] {logging_mixin.py:151} INFO - [2023-09-23T13:56:35.378+0000] {dagbag.py:347} ERROR - Failed to import: /workspaces/hands-on-introduction-data-engineering-4395021/airflow/dags/one-task-dag.py
Traceback (most recent call last):
  File "/usr/local/python/3.10.8/lib/python3.10/site-packages/airflow/models/dagbag.py", line 343, in parse
    loader.exec_module(new_module)
  File "<frozen importlib._bootstrap_external>", line 883, in exec_module
  File "<frozen importlib._bootstrap>", line 241, in _call_with_frames_removed
  File "/workspaces/hands-on-introduction-data-engineering-4395021/airflow/dags/one-task-dag.py", line 15, in <module>
    with DAG(
TypeError: DAG.__init__() got an unexpected keyword argument 'schedule_args'
[2023-09-23T13:56:35.381+0000] {processor.py:841} WARNING - No viable dags retrieved from /workspaces/hands-on-introduction-data-engineering-4395021/airflow/dags/one-task-dag.py
[2023-09-23T13:56:35.429+0000] {processor.py:179} INFO - Processing /workspaces/hands-on-introduction-data-engineering-4395021/airflow/dags/one-task-dag.py took 0.066 seconds
[2023-09-23T13:57:05.791+0000] {processor.py:157} INFO - Started process (PID=14162) to work on /workspaces/hands-on-introduction-data-engineering-4395021/airflow/dags/one-task-dag.py
[2023-09-23T13:57:05.791+0000] {processor.py:829} INFO - Processing file /workspaces/hands-on-introduction-data-engineering-4395021/airflow/dags/one-task-dag.py for tasks to queue
[2023-09-23T13:57:05.792+0000] {logging_mixin.py:151} INFO - [2023-09-23T13:57:05.792+0000] {dagbag.py:539} INFO - Filling up the DagBag from /workspaces/hands-on-introduction-data-engineering-4395021/airflow/dags/one-task-dag.py
[2023-09-23T13:57:05.793+0000] {logging_mixin.py:151} INFO - [2023-09-23T13:57:05.793+0000] {dagbag.py:347} ERROR - Failed to import: /workspaces/hands-on-introduction-data-engineering-4395021/airflow/dags/one-task-dag.py
Traceback (most recent call last):
  File "/usr/local/python/3.10.8/lib/python3.10/site-packages/airflow/models/dagbag.py", line 343, in parse
    loader.exec_module(new_module)
  File "<frozen importlib._bootstrap_external>", line 883, in exec_module
  File "<frozen importlib._bootstrap>", line 241, in _call_with_frames_removed
  File "/workspaces/hands-on-introduction-data-engineering-4395021/airflow/dags/one-task-dag.py", line 15, in <module>
    with DAG(
TypeError: DAG.__init__() got an unexpected keyword argument 'schedule_args'
[2023-09-23T13:57:05.794+0000] {processor.py:841} WARNING - No viable dags retrieved from /workspaces/hands-on-introduction-data-engineering-4395021/airflow/dags/one-task-dag.py
[2023-09-23T13:57:05.843+0000] {processor.py:179} INFO - Processing /workspaces/hands-on-introduction-data-engineering-4395021/airflow/dags/one-task-dag.py took 0.054 seconds
[2023-09-23T13:57:36.239+0000] {processor.py:157} INFO - Started process (PID=14363) to work on /workspaces/hands-on-introduction-data-engineering-4395021/airflow/dags/one-task-dag.py
[2023-09-23T13:57:36.240+0000] {processor.py:829} INFO - Processing file /workspaces/hands-on-introduction-data-engineering-4395021/airflow/dags/one-task-dag.py for tasks to queue
[2023-09-23T13:57:36.240+0000] {logging_mixin.py:151} INFO - [2023-09-23T13:57:36.240+0000] {dagbag.py:539} INFO - Filling up the DagBag from /workspaces/hands-on-introduction-data-engineering-4395021/airflow/dags/one-task-dag.py
[2023-09-23T13:57:36.242+0000] {logging_mixin.py:151} INFO - [2023-09-23T13:57:36.242+0000] {dagbag.py:347} ERROR - Failed to import: /workspaces/hands-on-introduction-data-engineering-4395021/airflow/dags/one-task-dag.py
Traceback (most recent call last):
  File "/usr/local/python/3.10.8/lib/python3.10/site-packages/airflow/models/dagbag.py", line 343, in parse
    loader.exec_module(new_module)
  File "<frozen importlib._bootstrap_external>", line 883, in exec_module
  File "<frozen importlib._bootstrap>", line 241, in _call_with_frames_removed
  File "/workspaces/hands-on-introduction-data-engineering-4395021/airflow/dags/one-task-dag.py", line 15, in <module>
    with DAG(
TypeError: DAG.__init__() got an unexpected keyword argument 'schedule_args'
[2023-09-23T13:57:36.242+0000] {processor.py:841} WARNING - No viable dags retrieved from /workspaces/hands-on-introduction-data-engineering-4395021/airflow/dags/one-task-dag.py
[2023-09-23T13:57:36.286+0000] {processor.py:179} INFO - Processing /workspaces/hands-on-introduction-data-engineering-4395021/airflow/dags/one-task-dag.py took 0.048 seconds
[2023-09-23T13:57:46.671+0000] {processor.py:157} INFO - Started process (PID=14432) to work on /workspaces/hands-on-introduction-data-engineering-4395021/airflow/dags/one-task-dag.py
[2023-09-23T13:57:46.672+0000] {processor.py:829} INFO - Processing file /workspaces/hands-on-introduction-data-engineering-4395021/airflow/dags/one-task-dag.py for tasks to queue
[2023-09-23T13:57:46.673+0000] {logging_mixin.py:151} INFO - [2023-09-23T13:57:46.673+0000] {dagbag.py:539} INFO - Filling up the DagBag from /workspaces/hands-on-introduction-data-engineering-4395021/airflow/dags/one-task-dag.py
[2023-09-23T13:57:46.685+0000] {processor.py:839} INFO - DAG(s) dict_keys(['one_task_dag']) retrieved from /workspaces/hands-on-introduction-data-engineering-4395021/airflow/dags/one-task-dag.py
[2023-09-23T13:57:46.933+0000] {logging_mixin.py:151} INFO - [2023-09-23T13:57:46.932+0000] {manager.py:499} INFO - Created Permission View: %s
[2023-09-23T13:57:46.984+0000] {logging_mixin.py:151} INFO - [2023-09-23T13:57:46.983+0000] {manager.py:499} INFO - Created Permission View: %s
[2023-09-23T13:57:47.028+0000] {logging_mixin.py:151} INFO - [2023-09-23T13:57:47.027+0000] {manager.py:499} INFO - Created Permission View: %s
[2023-09-23T13:57:47.028+0000] {logging_mixin.py:151} INFO - [2023-09-23T13:57:47.028+0000] {security.py:708} INFO - Not syncing DAG-level permissions for DAG 'DAG:one_task_dag' as access control is unset.
[2023-09-23T13:57:47.029+0000] {logging_mixin.py:151} INFO - [2023-09-23T13:57:47.028+0000] {dag.py:2915} INFO - Sync 1 DAGs
[2023-09-23T13:57:47.054+0000] {logging_mixin.py:151} INFO - [2023-09-23T13:57:47.054+0000] {dag.py:2937} INFO - Creating ORM DAG for one_task_dag
[2023-09-23T13:57:47.072+0000] {logging_mixin.py:151} INFO - [2023-09-23T13:57:47.072+0000] {dag.py:3696} INFO - Setting next_dagrun for one_task_dag to 2023-01-01T00:00:00+00:00, run_after=2023-01-02T00:00:00+00:00
[2023-09-23T13:57:47.156+0000] {processor.py:179} INFO - Processing /workspaces/hands-on-introduction-data-engineering-4395021/airflow/dags/one-task-dag.py took 0.487 seconds
