[2023-09-27T07:03:15.248+0000] {taskinstance.py:1157} INFO - Dependencies all met for dep_context=non-requeueable deps ti=<TaskInstance: ETL_dag.transform_task manual__2023-09-27T07:03:07.758214+00:00 [queued]>
[2023-09-27T07:03:15.253+0000] {taskinstance.py:1157} INFO - Dependencies all met for dep_context=requeueable deps ti=<TaskInstance: ETL_dag.transform_task manual__2023-09-27T07:03:07.758214+00:00 [queued]>
[2023-09-27T07:03:15.253+0000] {taskinstance.py:1359} INFO - Starting attempt 1 of 1
[2023-09-27T07:03:15.296+0000] {taskinstance.py:1380} INFO - Executing <Task(PythonOperator): transform_task> on 2023-09-27 07:03:07.758214+00:00
[2023-09-27T07:03:15.299+0000] {standard_task_runner.py:57} INFO - Started process 73748 to run task
[2023-09-27T07:03:15.302+0000] {standard_task_runner.py:84} INFO - Running: ['airflow', 'tasks', 'run', 'ETL_dag', 'transform_task', 'manual__2023-09-27T07:03:07.758214+00:00', '--job-id', '109', '--raw', '--subdir', 'DAGS_FOLDER/basic_etl_task.py', '--cfg-path', '/tmp/tmp9jgsmp4y']
[2023-09-27T07:03:15.302+0000] {standard_task_runner.py:85} INFO - Job 109: Subtask transform_task
[2023-09-27T07:03:15.397+0000] {task_command.py:415} INFO - Running <TaskInstance: ETL_dag.transform_task manual__2023-09-27T07:03:07.758214+00:00 [running]> on host codespaces-4967f6
[2023-09-27T07:03:15.536+0000] {taskinstance.py:1660} INFO - Exporting env vars: AIRFLOW_CTX_DAG_OWNER='airflow' AIRFLOW_CTX_DAG_ID='ETL_dag' AIRFLOW_CTX_TASK_ID='transform_task' AIRFLOW_CTX_EXECUTION_DATE='2023-09-27T07:03:07.758214+00:00' AIRFLOW_CTX_TRY_NUMBER='1' AIRFLOW_CTX_DAG_RUN_ID='manual__2023-09-27T07:03:07.758214+00:00'
[2023-09-27T07:03:15.537+0000] {taskinstance.py:1935} ERROR - Task failed with exception
Traceback (most recent call last):
  File "/usr/local/python/3.10.8/lib/python3.10/site-packages/airflow/operators/python.py", line 192, in execute
    return_value = self.execute_callable()
  File "/usr/local/python/3.10.8/lib/python3.10/site-packages/airflow/operators/python.py", line 209, in execute_callable
    return self.python_callable(*self.op_args, **self.op_kwargs)
  File "/workspaces/hands-on-introduction-data-engineering-4395021/airflow/dags/basic_etl_task.py", line 24, in transform_data
    df = pd.read_csv("/workspaces/hands-ons-introduction-data-engineering-4395021/lab/end-to-end/airflow-data-extract.csv")
  File "/home/codespace/.local/lib/python3.10/site-packages/pandas/io/parsers/readers.py", line 948, in read_csv
    return _read(filepath_or_buffer, kwds)
  File "/home/codespace/.local/lib/python3.10/site-packages/pandas/io/parsers/readers.py", line 611, in _read
    parser = TextFileReader(filepath_or_buffer, **kwds)
  File "/home/codespace/.local/lib/python3.10/site-packages/pandas/io/parsers/readers.py", line 1448, in __init__
    self._engine = self._make_engine(f, self.engine)
  File "/home/codespace/.local/lib/python3.10/site-packages/pandas/io/parsers/readers.py", line 1705, in _make_engine
    self.handles = get_handle(
  File "/home/codespace/.local/lib/python3.10/site-packages/pandas/io/common.py", line 863, in get_handle
    handle = open(
FileNotFoundError: [Errno 2] No such file or directory: '/workspaces/hands-ons-introduction-data-engineering-4395021/lab/end-to-end/airflow-data-extract.csv'
[2023-09-27T07:03:15.540+0000] {taskinstance.py:1398} INFO - Marking task as FAILED. dag_id=ETL_dag, task_id=transform_task, execution_date=20230927T070307, start_date=20230927T070315, end_date=20230927T070315
[2023-09-27T07:03:15.578+0000] {standard_task_runner.py:104} ERROR - Failed to execute job 109 for task transform_task ([Errno 2] No such file or directory: '/workspaces/hands-ons-introduction-data-engineering-4395021/lab/end-to-end/airflow-data-extract.csv'; 73748)
[2023-09-27T07:03:15.593+0000] {local_task_job_runner.py:228} INFO - Task exited with return code 1
[2023-09-27T07:03:15.659+0000] {taskinstance.py:2776} INFO - 0 downstream tasks scheduled from follow-on schedule check
