[2023-09-27T07:01:56.206+0000] {taskinstance.py:1157} INFO - Dependencies all met for dep_context=non-requeueable deps ti=<TaskInstance: ETL_dag.transform_task manual__2023-09-27T07:01:47.903579+00:00 [queued]>
[2023-09-27T07:01:56.211+0000] {taskinstance.py:1157} INFO - Dependencies all met for dep_context=requeueable deps ti=<TaskInstance: ETL_dag.transform_task manual__2023-09-27T07:01:47.903579+00:00 [queued]>
[2023-09-27T07:01:56.211+0000] {taskinstance.py:1359} INFO - Starting attempt 1 of 1
[2023-09-27T07:01:56.257+0000] {taskinstance.py:1380} INFO - Executing <Task(PythonOperator): transform_task> on 2023-09-27 07:01:47.903579+00:00
[2023-09-27T07:01:56.260+0000] {standard_task_runner.py:57} INFO - Started process 72937 to run task
[2023-09-27T07:01:56.262+0000] {standard_task_runner.py:84} INFO - Running: ['airflow', 'tasks', 'run', 'ETL_dag', 'transform_task', 'manual__2023-09-27T07:01:47.903579+00:00', '--job-id', '107', '--raw', '--subdir', 'DAGS_FOLDER/basic_etl_task.py', '--cfg-path', '/tmp/tmpetccgnh9']
[2023-09-27T07:01:56.263+0000] {standard_task_runner.py:85} INFO - Job 107: Subtask transform_task
[2023-09-27T07:01:56.312+0000] {task_command.py:415} INFO - Running <TaskInstance: ETL_dag.transform_task manual__2023-09-27T07:01:47.903579+00:00 [running]> on host codespaces-4967f6
[2023-09-27T07:01:56.417+0000] {taskinstance.py:1660} INFO - Exporting env vars: AIRFLOW_CTX_DAG_OWNER='airflow' AIRFLOW_CTX_DAG_ID='ETL_dag' AIRFLOW_CTX_TASK_ID='transform_task' AIRFLOW_CTX_EXECUTION_DATE='2023-09-27T07:01:47.903579+00:00' AIRFLOW_CTX_TRY_NUMBER='1' AIRFLOW_CTX_DAG_RUN_ID='manual__2023-09-27T07:01:47.903579+00:00'
[2023-09-27T07:01:56.418+0000] {taskinstance.py:1935} ERROR - Task failed with exception
Traceback (most recent call last):
  File "/usr/local/python/3.10.8/lib/python3.10/site-packages/airflow/operators/python.py", line 192, in execute
    return_value = self.execute_callable()
  File "/usr/local/python/3.10.8/lib/python3.10/site-packages/airflow/operators/python.py", line 209, in execute_callable
    return self.python_callable(*self.op_args, **self.op_kwargs)
  File "/workspaces/hands-on-introduction-data-engineering-4395021/airflow/dags/basic_etl_task.py", line 24, in transform_data
    df = pd.read_csv("/workspaces/hands-ons-introduction-data-engineering-4395021/lab/end-to-end/airflow-data-extract.csv")
  File "/home/codespace/.local/lib/python3.10/site-packages/pandas/io/parsers/readers.py", line 948, in read_csv
    return _read(filepath_or_buffer, kwds)
  File "/home/codespace/.local/lib/python3.10/site-packages/pandas/io/parsers/readers.py", line 611, in _read
    parser = TextFileReader(filepath_or_buffer, **kwds)
  File "/home/codespace/.local/lib/python3.10/site-packages/pandas/io/parsers/readers.py", line 1448, in __init__
    self._engine = self._make_engine(f, self.engine)
  File "/home/codespace/.local/lib/python3.10/site-packages/pandas/io/parsers/readers.py", line 1705, in _make_engine
    self.handles = get_handle(
  File "/home/codespace/.local/lib/python3.10/site-packages/pandas/io/common.py", line 863, in get_handle
    handle = open(
FileNotFoundError: [Errno 2] No such file or directory: '/workspaces/hands-ons-introduction-data-engineering-4395021/lab/end-to-end/airflow-data-extract.csv'
[2023-09-27T07:01:56.421+0000] {taskinstance.py:1398} INFO - Marking task as FAILED. dag_id=ETL_dag, task_id=transform_task, execution_date=20230927T070147, start_date=20230927T070156, end_date=20230927T070156
[2023-09-27T07:01:56.460+0000] {standard_task_runner.py:104} ERROR - Failed to execute job 107 for task transform_task ([Errno 2] No such file or directory: '/workspaces/hands-ons-introduction-data-engineering-4395021/lab/end-to-end/airflow-data-extract.csv'; 72937)
[2023-09-27T07:01:56.474+0000] {local_task_job_runner.py:228} INFO - Task exited with return code 1
[2023-09-27T07:01:56.487+0000] {taskinstance.py:2776} INFO - 0 downstream tasks scheduled from follow-on schedule check
